Traceback (most recent call last):
  File "/home/rodolpho/Projects/bayesian/BAYES/lib/python3.8/site-packages/jupyter_cache/executors/utils.py", line 51, in single_nb_execution
    executenb(
  File "/home/rodolpho/Projects/bayesian/BAYES/lib/python3.8/site-packages/nbclient/client.py", line 1117, in execute
    return NotebookClient(nb=nb, resources=resources, km=km, **kwargs).execute()
  File "/home/rodolpho/Projects/bayesian/BAYES/lib/python3.8/site-packages/nbclient/util.py", line 78, in wrapped
    return just_run(coro(*args, **kwargs))
  File "/home/rodolpho/Projects/bayesian/BAYES/lib/python3.8/site-packages/nbclient/util.py", line 57, in just_run
    return loop.run_until_complete(coro)
  File "/usr/lib/python3.8/asyncio/base_events.py", line 616, in run_until_complete
    return future.result()
  File "/home/rodolpho/Projects/bayesian/BAYES/lib/python3.8/site-packages/nbclient/client.py", line 558, in async_execute
    await self.async_execute_cell(
  File "/home/rodolpho/Projects/bayesian/BAYES/lib/python3.8/site-packages/nbclient/client.py", line 862, in async_execute_cell
    self._check_raise_for_error(cell, exec_reply)
  File "/home/rodolpho/Projects/bayesian/BAYES/lib/python3.8/site-packages/nbclient/client.py", line 765, in _check_raise_for_error
    raise CellExecutionError.from_cell_and_msg(cell, exec_reply_content)
nbclient.exceptions.CellExecutionError: An error occurred while executing the following cell:
------------------
import numpy as np

from scipy import stats

import matplotlib.pyplot as plt
from matplotlib.gridspec import GridSpec

import pandas as pd

import networkx as nx
# from causalgraphicalmodels import CausalGraphicalModel

# import arviz as az
# ArviZ ships with style sheets!
# https://python.arviz.org/en/stable/examples/styles.html#example-styles
#az.style.use("arviz-darkgrid")

import xarray as xr

import pystan
import nest_asyncio

plt.style.use('default')
plt.rcParams['axes.facecolor'] = 'lightgray'

# To DAG's
import daft
from causalgraphicalmodels import CausalGraphicalModel
------------------

[0;31m---------------------------------------------------------------------------[0m
[0;31mModuleNotFoundError[0m                       Traceback (most recent call last)
[0;32m/tmp/ipykernel_12469/116283454.py[0m in [0;36m<module>[0;34m[0m
[1;32m     18[0m [0;32mimport[0m [0mxarray[0m [0;32mas[0m [0mxr[0m[0;34m[0m[0;34m[0m[0m
[1;32m     19[0m [0;34m[0m[0m
[0;32m---> 20[0;31m [0;32mimport[0m [0mpystan[0m[0;34m[0m[0;34m[0m[0m
[0m[1;32m     21[0m [0;32mimport[0m [0mnest_asyncio[0m[0;34m[0m[0;34m[0m[0m
[1;32m     22[0m [0;34m[0m[0m

[0;31mModuleNotFoundError[0m: No module named 'pystan'
ModuleNotFoundError: No module named 'pystan'

